<mujoco model="saturdayMASTER.SLDASM">
  <compiler angle="radian"/>
  <asset>
    <mesh name="base_link" file="base_link.STL"/>
    <mesh name="HR" file="HR.STL"/>
    <mesh name="TR" file="TR.STL"/>
    <mesh name="SR" file="SR.STL"/>
    <mesh name="FR" file="FR.STL"/>
    <mesh name="HL" file="HL.STL"/>
    <mesh name="TL" file="TL.STL"/>
    <mesh name="SL" file="SL.STL"/>
    <mesh name="FL" file="FL.STL"/>
    <mesh name="PCPC" file="PCPC.STL"/>
  </asset>
  <worldbody>
    <geom type="mesh" rgba="0.69804 0.69804 0.69804 1" mesh="base_link"/>
    <geom pos="0 0.1668 0.076047" type="mesh" rgba="0.69804 0.69804 0.69804 1" mesh="PCPC"/>
    <body name="HR" pos="0.116 0.0760307 0">
      <inertial pos="-0.0022112 -0.0074687 0.0012046" quat="0.610545 0.791982 -0.00018656 -0.000166422" mass="1.1716" diaginertia="0.0010107 0.000889554 0.000807186"/>
      <joint name="HR" pos="0 0 0" axis="0 -1 0" limited="false"/>
      <geom type="mesh" rgba="0.69804 0.69804 0.69804 1" mesh="HR"/>
      <body name="TR">
        <inertial pos="0.0032217 -1.4794e-12 -0.11697" quat="1 -2.44026e-05 0 0" mass="0.2485" diaginertia="0.00045966 0.00043118 6.6608e-05"/>
        <joint name="TR" pos="0 0 0" axis="-1 0 0" limited="false"/>
        <geom type="mesh" rgba="0.69804 0.69804 0.69804 1" mesh="TR"/>
        <body name="SR" pos="0 0 -0.2">
          <inertial pos="0.013454 -0.0086691 -0.1053" quat="0.999944 0.00459107 -0.00078075 0.00948332" mass="0.45579" diaginertia="0.000577103 0.000543322 0.000136545"/>
          <joint name="SR" pos="0 0 0" axis="1 0 0" limited="false"/>
          <geom type="mesh" rgba="0.69804 0.69804 0.69804 1" mesh="SR"/>
          <body name="FR" pos="0 0 -0.24">
            <inertial pos="6.2538e-06 0.015791 -0.026269" quat="0.71996 0.694016 0.000136179 -0.000175049" mass="0.12898" diaginertia="0.00019456 0.000193198 1.66785e-05"/>
            <joint name="FR" pos="0 0 0" axis="1 0 0" limited="false"/>
            <geom type="mesh" rgba="0.62745 0.62745 0.62745 1" mesh="FR"/>
          </body>
        </body>
      </body>
    </body>
    <body name="HL" pos="-0.116 0.0760307 0">
      <inertial pos="0.0022047 -0.0074687 0.0010787" quat="0.61048 0.791973 -0.00678111 0.00679143" mass="1.1716" diaginertia="0.00101075 0.00088951 0.000807185"/>
      <joint name="HL" pos="0 0 0" axis="0 -1 0" limited="false"/>
      <geom type="mesh" rgba="0.69804 0.69804 0.69804 1" mesh="HL"/>
      <body name="TL">
        <inertial pos="-0.0032217 1.4785e-12 -0.11697" quat="1 2.44026e-05 0 0" mass="0.2485" diaginertia="0.00045966 0.00043118 6.6608e-05"/>
        <joint name="TL" pos="0 0 0" axis="-1 0 0" limited="false"/>
        <geom type="mesh" rgba="0.69804 0.69804 0.69804 1" mesh="TL"/>
        <body name="SL" pos="0 0 -0.2">
          <inertial pos="-0.013454 -0.0086668 -0.10518" quat="0.999946 0.00483719 -2.73708e-05 -0.00918761" mass="0.45579" diaginertia="0.000577101 0.000543337 0.000136532"/>
          <joint name="SL" pos="0 0 0" axis="-1 0 0" limited="false"/>
          <geom type="mesh" rgba="0.69804 0.69804 0.69804 1" mesh="SL"/>
          <body name="FL" pos="0 0 -0.24">
            <inertial pos="6.2538e-06 0.015791 -0.026269" quat="0.71996 0.694016 0.000136179 -0.000175049" mass="0.12898" diaginertia="0.00019456 0.000193198 1.66785e-05"/>
            <joint name="FL" pos="0 0 0" axis="1 0 0" limited="false"/>
            <geom type="mesh" rgba="0.62745 0.62745 0.62745 1" mesh="FL"/>
          </body>
        </body>
      </body>
    </body>
  </worldbody>
</mujoco>
